Erros encountered in Stable diffusion training.

1. Make sure there is no hidden directory inside the images folder, for example i was having a .cache directory so i got the below error.

07/26/2024 08:32:58 - INFO - __main__ - Distributed environment: DistributedType.NO
Num processes: 1
Process index: 0
Local process index: 0
Device: cuda

Mixed precision type: no

/home/ubuntu/.local/lib/python3.12/site-packages/huggingface_hub/file_download.py:1150: FutureWarning: `resume_download` is deprecated and will be removed in version 1.0.0. Downloads always resume when possible. If you want to force a new download, use `force_download=True`.
  warnings.warn(
tokenizer/tokenizer_config.json: 100%|█████████| 737/737 [00:00<00:00, 7.60MB/s]
tokenizer/vocab.json: 100%|████████████████| 1.06M/1.06M [00:00<00:00, 52.2MB/s]
tokenizer/merges.txt: 100%|██████████████████| 525k/525k [00:00<00:00, 31.6MB/s]
tokenizer/special_tokens_map.json: 100%|███████| 472/472 [00:00<00:00, 6.69MB/s]
tokenizer_2/tokenizer_config.json: 100%|███████| 725/725 [00:00<00:00, 9.44MB/s]
tokenizer_2/special_tokens_map.json: 100%|█████| 460/460 [00:00<00:00, 6.11MB/s]
text_encoder/config.json: 100%|████████████████| 565/565 [00:00<00:00, 7.16MB/s]
You are using a model of type clip_text_model to instantiate a model of type . This is not supported for all configurations of models and can yield errors.
text_encoder_2/config.json: 100%|██████████████| 575/575 [00:00<00:00, 7.99MB/s]
You are using a model of type clip_text_model to instantiate a model of type . This is not supported for all configurations of models and can yield errors.
model_index.json: 100%|████████████████████████| 609/609 [00:00<00:00, 8.32MB/s]
scheduler/scheduler_config.json: 100%|█████████| 479/479 [00:00<00:00, 7.12MB/s]
{'rescale_betas_zero_snr', 'clip_sample_range', 'dynamic_thresholding_ratio', 'variance_type', 'thresholding'} was not found in config. Values will be initialized to default values.
model.safetensors: 100%|██████████████████████| 492M/492M [00:01<00:00, 422MB/s]
model.safetensors: 100%|████████████████████| 2.78G/2.78G [00:08<00:00, 319MB/s]
config.json: 100%|█████████████████████████████| 631/631 [00:00<00:00, 8.68MB/s]
diffusion_pytorch_model.safetensors: 100%|████| 335M/335M [00:02<00:00, 132MB/s]
{'mid_block_add_attention', 'latents_mean', 'use_quant_conv', 'shift_factor', 'latents_std', 'use_post_quant_conv'} was not found in config. Values will be initialized to default values.
unet/config.json: 100%|████████████████████| 1.68k/1.68k [00:00<00:00, 27.6MB/s]
diffusion_pytorch_model.safetensors: 100%|██| 10.3G/10.3G [01:19<00:00, 129MB/s]
{'attention_type', 'reverse_transformer_layers_per_block', 'dropout'} was not found in config. Values will be initialized to default values.
Traceback (most recent call last):
  File "/home/ubuntu/train_dreambooth_lora_sdxl.py", line 1984, in <module>
    main(args)
  File "/home/ubuntu/train_dreambooth_lora_sdxl.py", line 1415, in main
    train_dataset = DreamBoothDataset(
                    ^^^^^^^^^^^^^^^^^^
  File "/home/ubuntu/train_dreambooth_lora_sdxl.py", line 780, in __init__
    instance_images = [Image.open(path) for path in list(Path(instance_data_root).iterdir())]
                       ^^^^^^^^^^^^^^^^
  File "/home/ubuntu/.local/lib/python3.12/site-packages/PIL/Image.py", line 3431, in open
    fp = builtins.open(filename, "rb")
         ^^^^^^^^^^^^^^^^^^^^^^^^^^^^^
IsADirectoryError: [Errno 21] Is a directory: '/home/ubuntu/dog/.cache'
Traceback (most recent call last):
  File "/home/ubuntu/.local/bin/accelerate", line 8, in <module>
    sys.exit(main())
             ^^^^^^
  File "/home/ubuntu/.local/lib/python3.12/site-packages/accelerate/commands/accelerate_cli.py", line 46, in main
    args.func(args)
  File "/home/ubuntu/.local/lib/python3.12/site-packages/accelerate/commands/launch.py", line 1075, in launch_command
    simple_launcher(args)
  File "/home/ubuntu/.local/lib/python3.12/site-packages/accelerate/commands/launch.py", line 681, in simple_launcher
    raise subprocess.CalledProcessError(returncode=process.returncode, cmd=cmd)
subprocess.CalledProcessError: Command '['/usr/bin/python3', 'train_dreambooth_lora_sdxl.py', '--pretrained_model_name_or_path=stabilityai/stable-diffusion-xl-base-1.0', '--instance_data_dir=dog', '--pretrained_vae_model_name_or_path=madebyollin/sdxl-vae-fp16-fix', '--output_dir=lora-trained-xl', '--mixed_precision=no', '--instance_prompt=a photo of sks man', '--resolution=512', '--train_batch_size=1', '--gradient_accumulation_steps=4', '--learning_rate=1e-4', '--report_to=tensorboard', '--lr_scheduler=constant', '--lr_warmup_steps=0', '--max_train_steps=500', '--checkpointing_steps=717']' returned non-zero exit status 1.

Solution :- remove the .cache directory inside the /home/ubuntu/dog directory.




Error 2 :- Make sure your Numpy version is correct.

7/26/2024 08:40:36 - INFO - __main__ - Distributed environment: DistributedType.NO
Num processes: 1
Process index: 0
Local process index: 0
Device: cuda

Mixed precision type: no

/home/ubuntu/.local/lib/python3.12/site-packages/huggingface_hub/file_download.py:1150: FutureWarning: `resume_download` is deprecated and will be removed in version 1.0.0. Downloads always resume when possible. If you want to force a new download, use `force_download=True`.
  warnings.warn(
You are using a model of type clip_text_model to instantiate a model of type . This is not supported for all configurations of models and can yield errors.
You are using a model of type clip_text_model to instantiate a model of type . This is not supported for all configurations of models and can yield errors.
{'thresholding', 'rescale_betas_zero_snr', 'dynamic_thresholding_ratio', 'variance_type', 'clip_sample_range'} was not found in config. Values will be initialized to default values.
{'use_post_quant_conv', 'latents_std', 'latents_mean', 'use_quant_conv', 'mid_block_add_attention', 'shift_factor'} was not found in config. Values will be initialized to default values.
{'reverse_transformer_layers_per_block', 'dropout', 'attention_type'} was not found in config. Values will be initialized to default values.
Traceback (most recent call last):
  File "/home/ubuntu/train_dreambooth_lora_sdxl.py", line 1984, in <module>
    main(args)
  File "/home/ubuntu/train_dreambooth_lora_sdxl.py", line 1543, in main
    accelerator.init_trackers(tracker_name, config=vars(args))
  File "/home/ubuntu/.local/lib/python3.12/site-packages/accelerate/accelerator.py", line 669, in _inner
    return PartialState().on_main_process(function)(*args, **kwargs)
           ^^^^^^^^^^^^^^^^^^^^^^^^^^^^^^^^^^^^^^^^^^^^^^^^^^^^^^^^^
  File "/home/ubuntu/.local/lib/python3.12/site-packages/accelerate/accelerator.py", line 2454, in init_trackers
    tracker.store_init_configuration(config)
  File "/home/ubuntu/.local/lib/python3.12/site-packages/accelerate/tracking.py", line 79, in execute_on_main_process
    return PartialState().on_main_process(function)(self, *args, **kwargs)
           ^^^^^^^^^^^^^^^^^^^^^^^^^^^^^^^^^^^^^^^^^^^^^^^^^^^^^^^^^^^^^^^
  File "/home/ubuntu/.local/lib/python3.12/site-packages/accelerate/tracking.py", line 211, in store_init_configuration
    self.writer.add_hparams(values, metric_dict={})
  File "/home/ubuntu/.local/lib/python3.12/site-packages/torch/utils/tensorboard/writer.py", line 330, in add_hparams
    exp, ssi, sei = hparams(hparam_dict, metric_dict, hparam_domain_discrete)
                    ^^^^^^^^^^^^^^^^^^^^^^^^^^^^^^^^^^^^^^^^^^^^^^^^^^^^^^^^^
  File "/home/ubuntu/.local/lib/python3.12/site-packages/torch/utils/tensorboard/summary.py", line 194, in hparams
    from tensorboard.plugins.hparams.metadata import (
  File "/home/ubuntu/.local/lib/python3.12/site-packages/tensorboard/plugins/hparams/metadata.py", line 32, in <module>
    NULL_TENSOR = tensor_util.make_tensor_proto(
                  ^^^^^^^^^^^^^^^^^^^^^^^^^^^^^^
  File "/home/ubuntu/.local/lib/python3.12/site-packages/tensorboard/util/tensor_util.py", line 405, in make_tensor_proto
    numpy_dtype = dtypes.as_dtype(nparray.dtype)
                  ^^^^^^^^^^^^^^^^^^^^^^^^^^^^^^
  File "/home/ubuntu/.local/lib/python3.12/site-packages/tensorboard/compat/tensorflow_stub/dtypes.py", line 677, in as_dtype
    if type_value.type == np.string_ or type_value.type == np.unicode_:
                          ^^^^^^^^^^
  File "/home/ubuntu/.local/lib/python3.12/site-packages/numpy/__init__.py", line 397, in __getattr__
    raise AttributeError(
AttributeError: `np.string_` was removed in the NumPy 2.0 release. Use `np.bytes_` instead.. Did you mean: 'strings'?
Traceback (most recent call last):
  File "/home/ubuntu/.local/bin/accelerate", line 8, in <module>
    sys.exit(main())
             ^^^^^^
  File "/home/ubuntu/.local/lib/python3.12/site-packages/accelerate/commands/accelerate_cli.py", line 46, in main
    args.func(args)
  File "/home/ubuntu/.local/lib/python3.12/site-packages/accelerate/commands/launch.py", line 1075, in launch_command
    simple_launcher(args)
  File "/home/ubuntu/.local/lib/python3.12/site-packages/accelerate/commands/launch.py", line 681, in simple_launcher
    raise subprocess.CalledProcessError(returncode=process.returncode, cmd=cmd)
subprocess.CalledProcessError: Command '['/usr/bin/python3', 'train_dreambooth_lora_sdxl.py', '--pretrained_model_name_or_path=stabilityai/stable-diffusion-xl-base-1.0', '--instance_data_dir=ansz', '--pretrained_vae_model_name_or_path=madebyollin/sdxl-vae-fp16-fix', '--output_dir=lora-trained-xl', '--mixed_precision=no', '--instance_prompt=a photo of sks man', '--resolution=512', '--train_batch_size=1', '--gradient_accumulation_steps=4', '--learning_rate=1e-4', '--report_to=tensorboard', '--lr_scheduler=constant', '--lr_warmup_steps=0', '--max_train_steps=500', '--checkpointing_steps=717']' returned non-zero exit status 1.

Solution :- install the correct Numpy version.
!pip install numpy==1.26.4
